<?xml version="1.0" ?>
<robot name="mini_cheetah_vision">
     <!-- Base -->
    <link name="base">
        <inertial><mass value="3.3"/><origin xyz="0.0 0.0 0.0"/><inertia ixx="0.011253" ixy="0" ixz="0" iyy="0.362030" iyz="0" izz="0.042673"/></inertial>
        <visual><geometry><mesh filename="meshes/mini_vision_body.dae"/></geometry><origin rpy="0.0 0.0 0.0" xyz="0.0 0.0 0.0"/></visual>
        <collision><geometry><mesh filename="meshes/mini_vision_body.dae"/></geometry><origin rpy="0 0 0" xyz="0 0 0"/></collision>
    </link>

    <!-- LF Leg -->
    <!-- LF Hip and HAA -->
    <joint name="LF_HAA" type="revolute">
        <axis xyz="1 0 0"/><origin rpy="0 0 0" xyz="0.14775 0.049 0.0"/>
        <parent link="base"/><child link="LF_HIP"/>
        <limit effort="18" lower="-1.6" upper="1.6" velocity="40"/>
    </joint>

    <link name="LF_HIP">
        <inertial><mass value="0.54"/><origin xyz="0.055 0.036 0."/><inertia ixx="0.000381" ixy="0.000058" ixz="0.00000045" iyy="0.000560" iyz="0.00000095" izz="0.000444"/></inertial>
        <visual><geometry><mesh filename="meshes/mini_vision_abd.dae"/></geometry><origin rpy="3.141592 0.0 0.0" xyz="0.0 0.0 0.0"/></visual>
        <collision><geometry><mesh filename="meshes/mini_vision_abd.dae"/></geometry><origin rpy="3.141592 0. 0." xyz="0. 0 0"/></collision>
    </link>

    <!-- LF Thigh and HFE -->
    <joint name="LF_HFE" type="revolute">
        <axis xyz="0 -1 0"/><origin rpy="0.0 0.0 0.0" xyz="0.055 0.019 0.00"/>
        <parent link="LF_HIP"/><child link="LF_THIGH"/>
        <limit effort="18" lower="-2.6" upper="2.6" velocity="40"/>
    </joint>

    <link name="LF_THIGH">
        <inertial><mass value="0.634"/><origin xyz="0.0 0.016 -0.02"/><inertia ixx="0.001983" ixy="0.000245" ixz="0.000013" iyy="0.002103" iyz="0.0000015" izz="0.000408"/></inertial>
        <visual><geometry><mesh filename="meshes/mini_vision_upper_leg.dae"/></geometry><origin rpy="0.0 0 3.141592" xyz="0.0 0.0 0.0"/></visual>
        <collision><geometry><mesh filename="meshes/mini_vision_upper_leg.dae"/></geometry><origin rpy="0 0 3.141592" xyz="0 0 0"/></collision>
    </link>

    <!-- LF Shank and KFE -->
    <joint name="LF_KFE" type="revolute">
        <axis xyz="0 -1 0"/><origin rpy="0.0 0 0.0" xyz="0.0 0.049 -0.2085"/>
        <parent link="LF_THIGH"/><child link="LF_SHANK"/>
        <limit effort="26" lower="-2.6" upper="2.6" velocity="26"/>
    </joint>

    <link name="LF_SHANK">
        <inertial><mass value="0.064"/><origin xyz="0.0 0.0 -0.061"/><inertia ixx="0.000245" ixy="0" ixz="0.0" iyy="0.000248" iyz="0" izz="0.000006"/></inertial>
        <visual><geometry><mesh filename="meshes/lower_leg.dae"/></geometry><origin rpy="0.0 0.0 3.141592" xyz="0.0 0.0 0.0"/></visual>
        <collision><geometry><mesh filename="meshes/lower_leg.dae"/></geometry><origin rpy="0 0 3.141592" xyz="0 0 0"/></collision>
    </link>
    
    <!-- LF FOOT -->
    <joint name="LF_SHANK_TO_FOOT" type="fixed" dont_collapse="true">    
        <parent link="LF_SHANK"/><child link="LF_FOOT"/>    
        <origin rpy="0.0 0.0 0.0" xyz="0.0 0.0 -0.22"/>
    </joint>  

    <link name="LF_FOOT">    
        <collision><origin xyz="0 0 0.0"/><geometry><sphere radius="0.02"/></geometry></collision>
        <inertial><origin rpy="0 0 0" xyz="0 0 0.0"/><mass value="0.01"/><inertia ixx="0" ixy="0" ixz="0" iyy="0" iyz="0" izz="0"/></inertial>
    </link>  

    <!-- RF Leg -->
    <!-- RF Hip and HAA -->
    <joint name="RF_HAA" type="revolute">
        <axis xyz="1 0 0"/><origin rpy="0 0 0" xyz="0.14775 -0.049 0.0"/>
        <parent link="base"/><child link="RF_HIP"/>
        <limit effort="18" lower="-1.6" upper="1.6" velocity="40"/>
    </joint>

    <link name="RF_HIP">
        <inertial><mass value="0.54"/><origin xyz="0.055 -0.036 0."/><inertia ixx="0.000381" ixy="0.000058" ixz="0.00000045" iyy="0.000560" iyz="0.00000095" izz="0.000444"/></inertial>
        <visual><geometry><mesh filename="meshes/mini_vision_abd.dae"/></geometry><origin rpy="0.0 0.0 0.0" xyz="0.0 0.0 0.0"/></visual>
        <collision><geometry><mesh filename="meshes/mini_vision_abd.dae"/></geometry><origin rpy="0. 0. 0." xyz="0. 0 0"/></collision>
    </link>

    <!-- RF Thigh and HFE -->
    <joint name="RF_HFE" type="revolute">
        <axis xyz="0 -1 0"/><origin rpy="0.0 0.0 0.0" xyz="0.055 -0.019 0.00"/>
        <parent link="RF_HIP"/><child link="RF_THIGH"/>
        <limit effort="18" lower="-2.6" upper="2.6" velocity="40"/>
    </joint>

    <link name="RF_THIGH">
        <inertial><mass value="0.634"/><origin xyz="0.0 0.016 -0.02"/><inertia ixx="0.001983" ixy="0.000245" ixz="0.000013" iyy="0.002103" iyz="0.0000015" izz="0.000408"/></inertial>
        <visual><geometry><mesh filename="meshes/mini_vision_upper_leg.dae"/></geometry><origin rpy="0.0 0.0 0.0" xyz="0.0 0.0 0.0"/></visual>
        <collision><geometry><mesh filename="meshes/mini_vision_upper_leg.dae"/></geometry><origin rpy="0 0 0" xyz="0 0 0"/></collision>
    </link>

    <!-- RF Shank and KFE -->
    <joint name="RF_KFE" type="revolute">
        <axis xyz="0 -1 0"/><origin rpy="0.0 0 0.0" xyz="0.0 -0.049 -0.2085"/>
        <parent link="RF_THIGH"/><child link="RF_SHANK"/>
        <limit effort="18" lower="-2.6" upper="2.6" velocity="40"/>
    </joint>

    <link name="RF_SHANK">
        <inertial><mass value="0.064"/><origin xyz="0.0 0.0 -0.061"/><inertia ixx="0.000245" ixy="0" ixz="0.0" iyy="0.000248" iyz="0" izz="0.000006"/></inertial>
        <visual><geometry><mesh filename="meshes/lower_leg.dae"/></geometry><origin rpy="0.0 0.0 0.0" xyz="0.0 0.0 0.0"/></visual>
        <collision><geometry><mesh filename="meshes/lower_leg.dae"/></geometry><origin rpy="0 0 0" xyz="0 0 0"/></collision>
    </link>

    <!-- RF FOOT -->
    <joint name="RF_SHANK_TO_FOOT" type="fixed" dont_collapse="true">    
        <parent link="RF_SHANK"/><child link="RF_FOOT"/>    
        <origin rpy="0.0 0.0 0.0" xyz="0.0 0.0 -0.22"/>
    </joint>  

    <link name="RF_FOOT">    
        <collision><origin xyz="0 0 0.0"/><geometry><sphere radius="0.02"/></geometry></collision>
        <inertial><origin rpy="0 0 0" xyz="0 0 0.0"/><mass value="0.01"/><inertia ixx="0" ixy="0" ixz="0" iyy="0" iyz="0" izz="0"/></inertial>
    </link>  

    
    <!-- LH Leg -->
    <!-- LH Hip and HAA -->
    <joint name="LH_HAA" type="revolute"><axis xyz="-1 0 0"/><origin rpy="0 3.141592 0" xyz="-0.14775 0.049 0.0"/>
    <parent link="base"/><child link="LH_HIP"/>
     <limit effort="18" lower="-1.6" upper="1.6" velocity="40"/>
    </joint>

    <link name="LH_HIP">
        <inertial><mass value="0.54"/><origin xyz="0.055 0.036 0."/><inertia ixx="0.000381" ixy="0.000058" ixz="0.00000045" iyy="0.000560" iyz="0.00000095" izz="0.000444"/></inertial>
        <visual><geometry><mesh filename="meshes/mini_vision_abd.dae"/></geometry><origin rpy="3.141592 0.0 0.0" xyz="0.0 0.0 0.0"/></visual>
        <collision><geometry><mesh filename="meshes/mini_vision_abd.dae"/></geometry><origin rpy="3.141592 0. 0." xyz="0. 0 0"/></collision>
    </link>

    <!-- LH Thigh and HFE -->
    <joint name="LH_HFE" type="revolute">
        <axis xyz="0 -1 0"/><origin rpy="0.0 3.141592 0.0" xyz="0.055 0.019 0.00"/>
        <parent link="LH_HIP"/><child link="LH_THIGH"/>
         <limit effort="18" lower="-2.6" upper="2.6" velocity="40"/>
    </joint>

    <link name="LH_THIGH">
        <inertial><mass value="0.634"/><origin xyz="0.0 0.016 -0.02"/><inertia ixx="0.001983" ixy="0.000245" ixz="0.000013" iyy="0.002103" iyz="0.0000015" izz="0.000408"/></inertial>
        <visual><geometry><mesh filename="meshes/mini_vision_upper_leg.dae"/></geometry><origin rpy="0.0 0 3.141592" xyz="0.0 0.0 0.0"/></visual>
        <collision><geometry><mesh filename="meshes/mini_vision_upper_leg.dae"/></geometry><origin rpy="0 0 3.141592" xyz="0 0 0"/></collision>
    </link>

    <!-- LH Shank and KFE -->
    <joint name="LH_KFE" type="revolute">
        <axis xyz="0 -1 0"/><origin rpy="0.0 0 0.0" xyz="0.0 0.049 -0.2085"/>
        <parent link="LH_THIGH"/><child link="LH_SHANK"/>
        <limit effort="18" lower="-2.6" upper="2.6" velocity="40"/>
    </joint>

    <link name="LH_SHANK">
        <inertial><mass value="0.064"/><origin xyz="0.0 0.0 -0.061"/><inertia ixx="0.000245" ixy="0" ixz="0.0" iyy="0.000248" iyz="0" izz="0.000006"/></inertial>
        <visual><geometry><mesh filename="meshes/lower_leg.dae"/></geometry><origin rpy="0.0 0.0 3.141592" xyz="0.0 0.0 0.0"/></visual>
        <collision><geometry><mesh filename="meshes/lower_leg.dae"/></geometry><origin rpy="0 0 3.141592" xyz="0 0 0"/></collision>
    </link>

    <!-- LH FOOT -->
    <joint name="LH_SHANK_TO_FOOT" type="fixed" dont_collapse="true">    
        <parent link="LH_SHANK"/><child link="LH_FOOT"/>    
        <origin rpy="0.0 0.0 0.0" xyz="0.0 0.0 -0.22"/>
    </joint>  

    <link name="LH_FOOT">    
        <collision><origin xyz="0 0 0.0"/><geometry><sphere radius="0.02"/></geometry></collision>
        <inertial><origin rpy="0 0 0" xyz="0 0 0.0"/><mass value="0.01"/><inertia ixx="0" ixy="0" ixz="0" iyy="0" iyz="0" izz="0"/></inertial>
    </link>

    <!-- RH Leg -->
    <!-- RH Hip and HAA -->
    <joint name="RH_HAA" type="revolute">
        <axis xyz="-1 0 0"/><origin rpy="0 3.141592 0" xyz="-0.14775 -0.049 0.0"/>
        <parent link="base"/><child link="RH_HIP"/>
        <limit effort="18" lower="-1.6" upper="1.6" velocity="40"/>
    </joint>

    <link name="RH_HIP">
        <inertial><mass value="0.54"/><origin xyz="0.055 -0.036 0."/><inertia ixx="0.000381" ixy="0.000058" ixz="0.00000045" iyy="0.000560" iyz="0.00000095" izz="0.000444"/></inertial>
        <visual><geometry><mesh filename="meshes/mini_vision_abd.dae"/></geometry><origin rpy="0.0 0.0 0.0" xyz="0.0 0.0 0.0"/></visual>
        <collision><geometry><mesh filename="meshes/mini_vision_abd.dae"/></geometry><origin rpy="0. 0. 0." xyz="0. 0 0"/></collision>
    </link>

    <!-- RH Thigh and HFE -->
    <joint name="RH_HFE" type="revolute">
        <axis xyz="0 -1 0"/><origin rpy="0.0 3.141592 0.0" xyz="0.055 -0.019 0.00"/>
        <parent link="RH_HIP"/><child link="RH_THIGH"/>
        <limit effort="18" lower="-2.6" upper="2.6" velocity="40"/>
    </joint>

    <link name="RH_THIGH">
        <inertial><mass value="0.634"/><origin xyz="0.0 0.016 -0.02"/><inertia ixx="0.001983" ixy="0.000245" ixz="0.000013" iyy="0.002103" iyz="0.0000015" izz="0.000408"/></inertial>
        <visual><geometry><mesh filename="meshes/mini_vision_upper_leg.dae"/></geometry><origin rpy="0.0 0.0 0.0" xyz="0.0 0.0 0.0"/></visual>
        <collision><geometry><mesh filename="meshes/mini_vision_upper_leg.dae"/></geometry><origin rpy="0 0 0" xyz="0 0 0"/></collision>
    </link>

    <!-- RH Shank and KFE -->
    <joint name="RH_KFE" type="revolute">
        <axis xyz="0 -1 0"/><origin rpy="0.0 0 0.0" xyz="0.0 -0.049 -0.2085"/>
        <parent link="RH_THIGH"/><child link="RH_SHANK"/>
        <limit effort="18" lower="-2.6" upper="2.6" velocity="40"/>
    </joint>

    <link name="RH_SHANK">
        <inertial><mass value="0.064"/><origin xyz="0.0 0.0 -0.061"/><inertia ixx="0.000245" ixy="0" ixz="0.0" iyy="0.000248" iyz="0" izz="0.000006"/></inertial>
        <visual><geometry><mesh filename="meshes/lower_leg.dae"/></geometry><origin rpy="0.0 0.0 0.0" xyz="0.0 0.0 0.0"/></visual>
        <collision><geometry><mesh filename="meshes/lower_leg.dae"/></geometry><origin rpy="0 0 0" xyz="0 0 0"/></collision>
    </link>

    <!-- RH FOOT -->
    <joint name="RH_SHANK_TO_FOOT" type="fixed" dont_collapse="true">    
        <parent link="RH_SHANK"/><child link="RH_FOOT"/>    
        <origin rpy="0.0 0.0 0.0" xyz="0.0 0.0 -0.22"/>
    </joint>  

    <link name="RH_FOOT">    
        <collision><origin xyz="0 0 0.0"/><geometry><sphere radius="0.02"/></geometry></collision>
        <inertial><origin rpy="0 0 0" xyz="0 0 0.0"/><mass value="0.01"/><inertia ixx="0" ixy="0" ixz="0" iyy="0" iyz="0" izz="0"/></inertial>
    </link>

</robot>
